[2024-07-14 10:21:21] 


[2024-07-14 10:21:21] Started the Error Log File
[2024-07-14 10:21:23] No errors occurred
[2024-07-14 10:21:23] Closed the Error Log File




[2024-07-14 10:31:45] 


[2024-07-14 10:31:45] Started the Error Log File
[2024-07-14 10:31:47] No errors occurred
[2024-07-14 10:31:47] Closed the Error Log File




[2024-07-14 10:31:59] 


[2024-07-14 10:31:59] Started the Error Log File
Exception in Tkinter callback
Traceback (most recent call last):
  File "C:\Users\wimjr\AppData\Local\Programs\Python\Python311\Lib\tkinter\__init__.py", line 1948, in __call__
    return self.func(*args)
           ^^^^^^^^^^^^^^^^
  File "C:\Users\wimjr\AppData\Local\Programs\Python\Python311\Lib\tkinter\__init__.py", line 861, in callit
    func(*args)
  File "e:\Snake_game_V3\Snake_Game_V3\Login\login_snake_game.py", line 126, in <lambda>
    self.result_label.after(1000, lambda: self.switch_to_user_screen(username))
                                          ^^^^^^^^^^^^^^^^^^^^^^^^^^
AttributeError: 'LoginAndUserScreen' object has no attribute 'switch_to_user_screen'
[2024-07-14 10:32:51] No errors occurred
[2024-07-14 10:32:51] Closed the Error Log File




[2024-07-14 10:33:30] 


[2024-07-14 10:33:30] Started the Error Log File
Exception in Tkinter callback
Traceback (most recent call last):
  File "C:\Users\wimjr\AppData\Local\Programs\Python\Python311\Lib\tkinter\__init__.py", line 1948, in __call__
    return self.func(*args)
           ^^^^^^^^^^^^^^^^
  File "C:\Users\wimjr\AppData\Local\Programs\Python\Python311\Lib\tkinter\__init__.py", line 861, in callit
    func(*args)
  File "e:\Snake_game_V3\Snake_Game_V3\Login\login_snake_game.py", line 126, in <lambda>
    self.result_label.after(1000, lambda: self.switch_to_user_screen(username))
                                          ^^^^^^^^^^^^^^^^^^^^^^^^^^
AttributeError: 'LoginAndUserScreen' object has no attribute 'switch_to_user_screen'
[2024-07-14 10:33:53] No errors occurred
[2024-07-14 10:33:53] Closed the Error Log File




[2024-07-14 10:38:37] 


[2024-07-14 10:38:37] Started the Error Log File
[2024-07-14 10:38:48] No errors occurred
[2024-07-14 10:38:48] Closed the Error Log File




[2024-07-14 10:42:35] 


[2024-07-14 10:42:35] Started the Error Log File
[2024-07-14 10:42:40] No errors occurred
[2024-07-14 10:42:40] Closed the Error Log File




[2024-07-14 10:42:43] 


[2024-07-14 10:42:43] Started the Error Log File
Exception in Tkinter callback
Traceback (most recent call last):
  File "C:\Users\wimjr\AppData\Local\Programs\Python\Python311\Lib\tkinter\__init__.py", line 1948, in __call__
    return self.func(*args)
           ^^^^^^^^^^^^^^^^
  File "C:\Users\wimjr\AppData\Local\Programs\Python\Python311\Lib\tkinter\__init__.py", line 861, in callit
    func(*args)
  File "e:\Snake_game_V3\Snake_Game_V3\Login\login_snake_game.py", line 127, in <lambda>
    self.result_label.after(1000, lambda: self.switch_to_user_screen(username))
                                          ^^^^^^^^^^^^^^^^^^^^^^^^^^^^^^^^^^^^
  File "e:\Snake_game_V3\Snake_Game_V3\Login\login_snake_game.py", line 184, in switch_to_user_screen
    self.on_login_success_callback(username)
TypeError: SnakeGameApp.show_loading_screen_after_login() takes 1 positional argument but 2 were given
[2024-07-14 10:42:59] No errors occurred
[2024-07-14 10:42:59] Closed the Error Log File




[2024-07-14 10:45:09] 


[2024-07-14 10:45:09] Started the Error Log File
Exception in Tkinter callback
Traceback (most recent call last):
  File "C:\Users\wimjr\AppData\Local\Programs\Python\Python311\Lib\tkinter\__init__.py", line 1948, in __call__
    return self.func(*args)
           ^^^^^^^^^^^^^^^^
  File "C:\Users\wimjr\AppData\Local\Programs\Python\Python311\Lib\tkinter\__init__.py", line 861, in callit
    func(*args)
  File "e:\Snake_game_V3\Snake_Game_V3\Login\login_snake_game.py", line 127, in <lambda>
    self.result_label.after(1000, lambda: self.switch_to_user_screen(username))
                                          ^^^^^^^^^^^^^^^^^^^^^^^^^^^^^^^^^^^^
  File "e:\Snake_game_V3\Snake_Game_V3\Login\login_snake_game.py", line 184, in switch_to_user_screen
    self.on_login_success_callback(username)
TypeError: SnakeGameApp.show_loading_screen_after_login() takes 1 positional argument but 2 were given
[2024-07-14 10:45:18] No errors occurred
[2024-07-14 10:45:18] Closed the Error Log File




[2024-07-14 10:47:25] 


[2024-07-14 10:47:25] Started the Error Log File
[2024-07-14 10:47:41] No errors occurred
[2024-07-14 10:47:41] Closed the Error Log File




[2024-07-14 10:48:57] 


[2024-07-14 10:48:57] Started the Error Log File
[2024-07-14 10:49:11] No errors occurred
[2024-07-14 10:49:11] Closed the Error Log File




[2024-07-14 10:49:46] 


[2024-07-14 10:49:46] Started the Error Log File
Exception in Tkinter callback
Traceback (most recent call last):
  File "C:\Users\wimjr\AppData\Local\Programs\Python\Python311\Lib\tkinter\__init__.py", line 1948, in __call__
    return self.func(*args)
           ^^^^^^^^^^^^^^^^
  File "C:\Users\wimjr\AppData\Local\Programs\Python\Python311\Lib\tkinter\__init__.py", line 861, in callit
    func(*args)
  File "e:\Snake_game_V3\Snake_Game_V3\Login\login_snake_game.py", line 143, in <lambda>
    self.result_label.after(3000, lambda: self.result_label.configure(text="", fg_color="black")) # pylint: disable=line-too-long
                                          ^^^^^^^^^^^^^^^^^^^^^^^^^^^^^^^^^^^^^^^^^^^^^^^^^^^^^^
  File "C:\Users\wimjr\AppData\Local\Programs\Python\Python311\Lib\site-packages\customtkinter\windows\widgets\ctk_label.py", line 206, in configure
    self._label.configure(text=self._text)
  File "C:\Users\wimjr\AppData\Local\Programs\Python\Python311\Lib\tkinter\__init__.py", line 1702, in configure
    return self._configure('configure', cnf, kw)
           ^^^^^^^^^^^^^^^^^^^^^^^^^^^^^^^^^^^^^
  File "C:\Users\wimjr\AppData\Local\Programs\Python\Python311\Lib\tkinter\__init__.py", line 1692, in _configure
    self.tk.call(_flatten((self._w, cmd)) + self._options(cnf))
_tkinter.TclError: invalid command name ".!ctkframe2.!ctklabel3.!label"
[2024-07-14 10:50:02] No errors occurred
[2024-07-14 10:50:02] Closed the Error Log File




[2024-07-14 10:51:09] 


[2024-07-14 10:51:09] Started the Error Log File
[2024-07-14 10:51:19] No errors occurred
[2024-07-14 10:51:19] Closed the Error Log File




[2024-07-14 10:51:51] 


[2024-07-14 10:51:51] Started the Error Log File
[2024-07-14 10:56:31] No errors occurred
[2024-07-14 10:56:31] Closed the Error Log File




[2024-07-14 11:01:38] 


[2024-07-14 11:01:38] Started the Error Log File
[2024-07-14 11:13:50] No errors occurred
[2024-07-14 11:13:50] Closed the Error Log File




[2024-07-14 11:14:08] 


[2024-07-14 11:14:08] Started the Error Log File
[2024-07-14 11:23:32] No errors occurred
[2024-07-14 11:23:32] Closed the Error Log File




[2024-07-14 11:23:44] 


[2024-07-14 11:23:44] Started the Error Log File
[2024-07-14 11:24:23] No errors occurred
[2024-07-14 11:24:23] Closed the Error Log File




[2024-07-14 11:24:33] 


[2024-07-14 11:24:33] Started the Error Log File
[2024-07-14 11:24:40] No errors occurred
[2024-07-14 11:24:40] Closed the Error Log File




[2024-07-14 11:30:46] 


[2024-07-14 11:30:46] Started the Error Log File
[2024-07-14 11:33:48] No errors occurred
[2024-07-14 11:33:48] Closed the Error Log File




[2024-07-14 11:38:49] 


[2024-07-14 11:38:49] Started the Error Log File
[2024-07-14 11:40:48] No errors occurred
[2024-07-14 11:40:48] Closed the Error Log File




[2024-07-14 11:40:49] 


[2024-07-14 11:40:49] Started the Error Log File
[2024-07-14 11:41:02] No errors occurred
[2024-07-14 11:41:02] Closed the Error Log File




[2024-07-14 11:42:13] 


[2024-07-14 11:42:13] Started the Error Log File
Exception in Tkinter callback
Traceback (most recent call last):
  File "C:\Users\wimjr\AppData\Local\Programs\Python\Python311\Lib\tkinter\__init__.py", line 1948, in __call__
    return self.func(*args)
           ^^^^^^^^^^^^^^^^
  File "C:\Users\wimjr\AppData\Local\Programs\Python\Python311\Lib\tkinter\__init__.py", line 861, in callit
    func(*args)
  File "e:\Snake_game_V3\Snake_Game_V3\main_snake_game.py", line 376, in destroy_loading_screen
    self.create_home_screen()
  File "e:\Snake_game_V3\Snake_Game_V3\main_snake_game.py", line 422, in create_home_screen
    self.username_label = ctk.CTkLabel(self.main_canvas, text=f"User: {self.get_user_name}", font=("Helvetica", 20), fg="white", bg="Grey20") # pylint: disable=line-too-long
                          ^^^^^^^^^^^^^^^^^^^^^^^^^^^^^^^^^^^^^^^^^^^^^^^^^^^^^^^^^^^^^^^^^^^^^^^^^^^^^^^^^^^^^^^^^^^^^^^^^^^^^^^^^^^^^^^^^^^
  File "C:\Users\wimjr\AppData\Local\Programs\Python\Python311\Lib\site-packages\customtkinter\windows\widgets\ctk_label.py", line 101, in __init__
    check_kwargs_empty(kwargs, raise_error=True)
  File "C:\Users\wimjr\AppData\Local\Programs\Python\Python311\Lib\site-packages\customtkinter\windows\widgets\utility\utility_functions.py", line 18, in check_kwargs_empty
    raise ValueError(f"{list(kwargs_dict.keys())} are not supported arguments. Look at the documentation for supported arguments.")
ValueError: ['fg', 'bg'] are not supported arguments. Look at the documentation for supported arguments.
[2024-07-14 11:42:40] No errors occurred
[2024-07-14 11:42:40] Closed the Error Log File




[2024-07-14 11:42:41] 


[2024-07-14 11:42:41] Started the Error Log File
Exception in Tkinter callback
Traceback (most recent call last):
  File "C:\Users\wimjr\AppData\Local\Programs\Python\Python311\Lib\tkinter\__init__.py", line 1948, in __call__
    return self.func(*args)
           ^^^^^^^^^^^^^^^^
  File "C:\Users\wimjr\AppData\Local\Programs\Python\Python311\Lib\tkinter\__init__.py", line 861, in callit
    func(*args)
  File "e:\Snake_game_V3\Snake_Game_V3\main_snake_game.py", line 376, in destroy_loading_screen
    self.create_home_screen()
  File "e:\Snake_game_V3\Snake_Game_V3\main_snake_game.py", line 422, in create_home_screen
    self.username_label = ctk.CTkLabel(self.main_canvas, text=f"User: {self.get_user_name}", font=("Helvetica", 20), fg="white", bg="Grey20") # pylint: disable=line-too-long
                          ^^^^^^^^^^^^^^^^^^^^^^^^^^^^^^^^^^^^^^^^^^^^^^^^^^^^^^^^^^^^^^^^^^^^^^^^^^^^^^^^^^^^^^^^^^^^^^^^^^^^^^^^^^^^^^^^^^^
  File "C:\Users\wimjr\AppData\Local\Programs\Python\Python311\Lib\site-packages\customtkinter\windows\widgets\ctk_label.py", line 101, in __init__
    check_kwargs_empty(kwargs, raise_error=True)
  File "C:\Users\wimjr\AppData\Local\Programs\Python\Python311\Lib\site-packages\customtkinter\windows\widgets\utility\utility_functions.py", line 18, in check_kwargs_empty
    raise ValueError(f"{list(kwargs_dict.keys())} are not supported arguments. Look at the documentation for supported arguments.")
ValueError: ['fg', 'bg'] are not supported arguments. Look at the documentation for supported arguments.
[2024-07-14 11:44:03] No errors occurred
[2024-07-14 11:44:03] Closed the Error Log File




[2024-07-14 11:44:04] 


[2024-07-14 11:44:04] Started the Error Log File
[2024-07-14 11:44:28] No errors occurred
[2024-07-14 11:44:28] Closed the Error Log File




[2024-07-14 11:44:29] 


[2024-07-14 11:44:29] Started the Error Log File
[2024-07-14 11:45:00] No errors occurred
[2024-07-14 11:45:00] Closed the Error Log File




[2024-07-14 11:45:02] 


[2024-07-14 11:45:02] Started the Error Log File
[2024-07-14 11:45:51] No errors occurred
[2024-07-14 11:45:51] Closed the Error Log File




[2024-07-14 11:45:53] 


[2024-07-14 11:45:53] Started the Error Log File
[2024-07-14 11:49:23] No errors occurred
[2024-07-14 11:49:23] Closed the Error Log File




[2024-07-14 11:49:24] 


[2024-07-14 11:49:24] Started the Error Log File
[2024-07-14 11:50:17] No errors occurred
[2024-07-14 11:50:17] Closed the Error Log File




[2024-07-14 11:50:18] 


[2024-07-14 11:50:18] Started the Error Log File
[2024-07-14 11:50:34] No errors occurred
[2024-07-14 11:50:34] Closed the Error Log File




[2024-07-14 11:50:35] 


[2024-07-14 11:50:35] Started the Error Log File
[2024-07-14 11:50:52] No errors occurred
[2024-07-14 11:50:52] Closed the Error Log File




[2024-07-14 11:50:53] 


[2024-07-14 11:50:53] Started the Error Log File
[2024-07-14 11:51:08] No errors occurred
[2024-07-14 11:51:08] Closed the Error Log File




[2024-07-14 11:51:09] 


[2024-07-14 11:51:09] Started the Error Log File
[2024-07-14 11:51:58] No errors occurred
[2024-07-14 11:51:58] Closed the Error Log File




[2024-07-14 11:51:59] 


[2024-07-14 11:51:59] Started the Error Log File
[2024-07-14 11:52:15] No errors occurred
[2024-07-14 11:52:15] Closed the Error Log File




[2024-07-14 11:52:16] 


[2024-07-14 11:52:16] Started the Error Log File
[2024-07-14 11:52:33] No errors occurred
[2024-07-14 11:52:33] Closed the Error Log File




[2024-07-14 11:52:34] 


[2024-07-14 11:52:34] Started the Error Log File
[2024-07-14 11:53:01] No errors occurred
[2024-07-14 11:53:01] Closed the Error Log File




[2024-07-14 11:53:03] 


[2024-07-14 11:53:03] Started the Error Log File
[2024-07-14 11:54:24] No errors occurred
[2024-07-14 11:54:24] Closed the Error Log File




[2024-07-14 11:54:25] 


[2024-07-14 11:54:25] Started the Error Log File
[2024-07-14 11:56:19] No errors occurred
[2024-07-14 11:56:19] Closed the Error Log File




[2024-07-14 11:56:21] 


[2024-07-14 11:56:21] Started the Error Log File
[2024-07-14 11:56:32] No errors occurred
[2024-07-14 11:56:32] Closed the Error Log File




[2024-07-14 11:59:10] 


[2024-07-14 11:59:10] Started the Error Log File
Exception in Tkinter callback
Traceback (most recent call last):
  File "C:\Users\wimjr\AppData\Local\Programs\Python\Python311\Lib\tkinter\__init__.py", line 1948, in __call__
    return self.func(*args)
           ^^^^^^^^^^^^^^^^
  File "C:\Users\wimjr\AppData\Local\Programs\Python\Python311\Lib\site-packages\customtkinter\windows\widgets\core_widget_classes\dropdown_menu.py", line 101, in <lambda>
    command=lambda v=value: self._button_callback(v),
                            ^^^^^^^^^^^^^^^^^^^^^^^^
  File "C:\Users\wimjr\AppData\Local\Programs\Python\Python311\Lib\site-packages\customtkinter\windows\widgets\core_widget_classes\dropdown_menu.py", line 106, in _button_callback
    self._command(value)
  File "C:\Users\wimjr\AppData\Local\Programs\Python\Python311\Lib\site-packages\customtkinter\windows\widgets\ctk_combobox.py", line 384, in _dropdown_callback
    self._command(value)
TypeError: LoginAndUserScreen.update_usernames_combobox() takes 1 positional argument but 2 were given
Exception in Tkinter callback
Traceback (most recent call last):
  File "C:\Users\wimjr\AppData\Local\Programs\Python\Python311\Lib\tkinter\__init__.py", line 1948, in __call__
    return self.func(*args)
           ^^^^^^^^^^^^^^^^
  File "C:\Users\wimjr\AppData\Local\Programs\Python\Python311\Lib\site-packages\customtkinter\windows\widgets\core_widget_classes\dropdown_menu.py", line 101, in <lambda>
    command=lambda v=value: self._button_callback(v),
                            ^^^^^^^^^^^^^^^^^^^^^^^^
  File "C:\Users\wimjr\AppData\Local\Programs\Python\Python311\Lib\site-packages\customtkinter\windows\widgets\core_widget_classes\dropdown_menu.py", line 106, in _button_callback
    self._command(value)
  File "C:\Users\wimjr\AppData\Local\Programs\Python\Python311\Lib\site-packages\customtkinter\windows\widgets\ctk_combobox.py", line 384, in _dropdown_callback
    self._command(value)
TypeError: LoginAndUserScreen.update_usernames_combobox() takes 1 positional argument but 2 were given
[2024-07-14 11:59:32] No errors occurred
[2024-07-14 11:59:32] Closed the Error Log File




[2024-07-14 11:59:46] 


[2024-07-14 11:59:46] Started the Error Log File
[2024-07-14 12:03:32] No errors occurred
[2024-07-14 12:03:32] Closed the Error Log File




[2024-07-14 12:03:35] 


[2024-07-14 12:03:35] Started the Error Log File
[2024-07-14 12:03:40] No errors occurred
[2024-07-14 12:03:40] Closed the Error Log File




[2024-07-14 12:04:11] 


[2024-07-14 12:04:11] Started the Error Log File
[2024-07-14 12:04:20] No errors occurred
[2024-07-14 12:04:20] Closed the Error Log File




[2024-07-14 12:05:05] 


[2024-07-14 12:05:05] Started the Error Log File
Exception in Tkinter callback
Traceback (most recent call last):
  File "C:\Users\wimjr\AppData\Local\Programs\Python\Python311\Lib\tkinter\__init__.py", line 1948, in __call__
    return self.func(*args)
           ^^^^^^^^^^^^^^^^
  File "C:\Users\wimjr\AppData\Local\Programs\Python\Python311\Lib\site-packages\customtkinter\windows\widgets\core_widget_classes\dropdown_menu.py", line 101, in <lambda>
    command=lambda v=value: self._button_callback(v),
                            ^^^^^^^^^^^^^^^^^^^^^^^^
  File "C:\Users\wimjr\AppData\Local\Programs\Python\Python311\Lib\site-packages\customtkinter\windows\widgets\core_widget_classes\dropdown_menu.py", line 106, in _button_callback
    self._command(value)
  File "C:\Users\wimjr\AppData\Local\Programs\Python\Python311\Lib\site-packages\customtkinter\windows\widgets\ctk_combobox.py", line 384, in _dropdown_callback
    self._command(value)
TypeError: LoginAndUserScreen.update_usernames_combobox() takes 1 positional argument but 2 were given
[2024-07-14 13:49:41] No errors occurred
[2024-07-14 13:49:41] Closed the Error Log File




[2024-07-14 13:49:44] 


[2024-07-14 13:49:44] Started the Error Log File
[2024-07-14 13:50:25] No errors occurred
[2024-07-14 13:50:25] Closed the Error Log File




[2024-07-14 13:50:27] 


[2024-07-14 13:50:27] Started the Error Log File
[2024-07-14 13:50:49] No errors occurred
[2024-07-14 13:50:49] Closed the Error Log File




[2024-07-14 13:51:01] 


[2024-07-14 13:51:01] Started the Error Log File
[2024-07-14 13:51:42] No errors occurred
[2024-07-14 13:51:42] Closed the Error Log File




[2024-07-14 13:51:44] 


[2024-07-14 13:51:44] Started the Error Log File
[2024-07-14 13:51:54] No errors occurred
[2024-07-14 13:51:54] Closed the Error Log File




[2024-07-14 13:51:56] 


[2024-07-14 13:51:56] Started the Error Log File
[2024-07-14 13:53:16] No errors occurred
[2024-07-14 13:53:16] Closed the Error Log File




[2024-07-14 13:53:18] 


[2024-07-14 13:53:18] Started the Error Log File
[2024-07-14 13:53:40] No errors occurred
[2024-07-14 13:53:40] Closed the Error Log File




[2024-07-14 13:53:42] 


[2024-07-14 13:53:42] Started the Error Log File
[2024-07-14 14:02:11] No errors occurred
[2024-07-14 14:02:11] Closed the Error Log File




[2024-07-17 19:41:10] 


[2024-07-17 19:41:10] Started the Error Log File
[2024-07-17 19:58:01] No errors occurred
[2024-07-17 19:58:01] Closed the Error Log File




[2024-07-17 19:58:04] 


[2024-07-17 19:58:04] Started the Error Log File
[2024-07-17 19:58:08] No errors occurred
[2024-07-17 19:58:08] Closed the Error Log File




[2024-07-17 19:58:14] 


[2024-07-17 19:58:14] Started the Error Log File
[2024-07-17 19:59:59] No errors occurred
[2024-07-17 19:59:59] Closed the Error Log File




[2024-07-17 20:00:02] 


[2024-07-17 20:00:02] Started the Error Log File
[2024-07-17 20:00:43] No errors occurred
[2024-07-17 20:00:43] Closed the Error Log File




[2024-07-17 20:00:45] 


[2024-07-17 20:00:45] Started the Error Log File
[2024-07-17 20:02:09] No errors occurred
[2024-07-17 20:02:09] Closed the Error Log File




[2024-07-17 20:02:11] 


[2024-07-17 20:02:11] Started the Error Log File
[2024-07-17 20:02:22] No errors occurred
[2024-07-17 20:02:22] Closed the Error Log File




[2024-07-17 20:02:24] 


[2024-07-17 20:02:24] Started the Error Log File
[2024-07-17 20:03:13] No errors occurred
[2024-07-17 20:03:13] Closed the Error Log File




[2024-07-17 20:03:16] 


[2024-07-17 20:03:16] Started the Error Log File
[2024-07-17 20:03:38] No errors occurred
[2024-07-17 20:03:38] Closed the Error Log File




[2024-07-17 20:03:41] 


[2024-07-17 20:03:41] Started the Error Log File
[2024-07-17 20:04:27] No errors occurred
[2024-07-17 20:04:27] Closed the Error Log File




[2024-07-17 20:04:29] 


[2024-07-17 20:04:29] Started the Error Log File
[2024-07-17 20:04:42] No errors occurred
[2024-07-17 20:04:42] Closed the Error Log File




[2024-07-17 20:04:44] 


[2024-07-17 20:04:44] Started the Error Log File
[2024-07-17 20:04:49] No errors occurred
[2024-07-17 20:04:49] Closed the Error Log File




[2024-07-17 20:04:57] 


[2024-07-17 20:04:57] Started the Error Log File
[2024-07-17 20:05:24] No errors occurred
[2024-07-17 20:05:24] Closed the Error Log File




[2024-07-17 20:05:27] 


[2024-07-17 20:05:27] Started the Error Log File
[2024-07-17 20:07:06] No errors occurred
[2024-07-17 20:07:06] Closed the Error Log File




[2024-07-19 20:07:08] 


[2024-07-19 20:07:08] Started the Error Log File
Traceback (most recent call last):
  File "e:\Snake_game_V3\Snake_Game_V3\main_snake_game.py", line 1284, in <module>
    app = SnakeGameApp(root, GameConstants.MIN_WIDTH, GameConstants.MIN_HEIGHT)
          ^^^^^^^^^^^^^^^^^^^^^^^^^^^^^^^^^^^^^^^^^^^^^^^^^^^^^^^^^^^^^^^^^^^^^
  File "e:\Snake_game_V3\Snake_Game_V3\main_snake_game.py", line 261, in __init__
    self.create_login_screen_main()
  File "e:\Snake_game_V3\Snake_Game_V3\main_snake_game.py", line 269, in create_login_screen_main
    self.login_screen.create_login_screen()
  File "e:\Snake_game_V3\Snake_Game_V3\Login\login_snake_game.py", line 82, in create_login_screen
    self.create_and_place_image_label(self.login_frame, 5, 635, self.config_path_icon)
  File "e:\Snake_game_V3\Snake_Game_V3\Login\login_snake_game.py", line 91, in create_and_place_image_label
    my_image = ctk.CTkImage(light_image=Image.open(image_path),
                                        ^^^^^^^^^^^^^^^^^^^^^^
  File "C:\Users\wimjr\AppData\Local\Programs\Python\Python311\Lib\site-packages\PIL\Image.py", line 3243, in open
    fp = builtins.open(filename, "rb")
         ^^^^^^^^^^^^^^^^^^^^^^^^^^^^^
FileNotFoundError: [Errno 2] No such file or directory: 'e:\\Snake_game_V3\\Snake_Game_V3\\Login\\app_icon.ico'
[2024-07-19 19:56:10] 


[2024-07-19 19:56:10] Started the Error Log File
[2024-07-19 20:09:14] No errors occurred
[2024-07-19 20:09:14] Closed the Error Log File




[2024-07-19 20:08:10] 


[2024-07-19 20:08:10] Started the Error Log File
[2024-07-19 20:09:18] No errors occurred
[2024-07-19 20:09:18] Closed the Error Log File




[2024-07-19 20:09:15] 


[2024-07-19 20:09:15] Started the Error Log File
[2024-07-19 20:09:23] No errors occurred
[2024-07-19 20:09:23] Closed the Error Log File




[2024-07-19 20:09:24] 


[2024-07-19 20:09:24] Started the Error Log File
[2024-07-19 20:09:25] No errors occurred
[2024-07-19 20:09:25] Closed the Error Log File




[2024-07-19 20:09:56] 


[2024-07-19 20:09:56] Started the Error Log File
[2024-07-19 20:16:00] No errors occurred
[2024-07-19 20:16:00] Closed the Error Log File




[2024-07-19 20:16:02] 


[2024-07-19 20:16:02] Started the Error Log File
Traceback (most recent call last):
  File "e:\Snake_game_V3\Snake_Game_V3\main_snake_game.py", line 1284, in <module>
    app = SnakeGameApp(root, GameConstants.MIN_WIDTH, GameConstants.MIN_HEIGHT)
          ^^^^^^^^^^^^^^^^^^^^^^^^^^^^^^^^^^^^^^^^^^^^^^^^^^^^^^^^^^^^^^^^^^^^^
  File "e:\Snake_game_V3\Snake_Game_V3\main_snake_game.py", line 261, in __init__
    self.create_login_screen_main()
  File "e:\Snake_game_V3\Snake_Game_V3\main_snake_game.py", line 269, in create_login_screen_main
    self.login_screen.create_login_screen()
  File "e:\Snake_game_V3\Snake_Game_V3\Login\login_snake_game.py", line 82, in create_login_screen
    self.create_and_place_image_label(self.login_frame, 5, 635, self.config_path_icon)
  File "e:\Snake_game_V3\Snake_Game_V3\Login\login_snake_game.py", line 103, in create_and_place_image_label
    my_ctk_image = ctk.CTkImage(image=my_image)
                   ^^^^^^^^^^^^^^^^^^^^^^^^^^^^
TypeError: CTkImage.__init__() got an unexpected keyword argument 'image'
[2024-07-19 20:19:16] 


[2024-07-19 20:19:16] Started the Error Log File
[2024-07-19 20:27:05] No errors occurred
[2024-07-19 20:27:05] Closed the Error Log File




[2024-07-19 20:27:07] 


[2024-07-19 20:27:07] Started the Error Log File
Traceback (most recent call last):
  File "e:\Snake_game_V3\Snake_Game_V3\main_snake_game.py", line 1284, in <module>
    app = SnakeGameApp(root, GameConstants.MIN_WIDTH, GameConstants.MIN_HEIGHT)
          ^^^^^^^^^^^^^^^^^^^^^^^^^^^^^^^^^^^^^^^^^^^^^^^^^^^^^^^^^^^^^^^^^^^^^
  File "e:\Snake_game_V3\Snake_Game_V3\main_snake_game.py", line 261, in __init__
    self.create_login_screen_main()
  File "e:\Snake_game_V3\Snake_Game_V3\main_snake_game.py", line 269, in create_login_screen_main
    self.login_screen.create_login_screen()
  File "e:\Snake_game_V3\Snake_Game_V3\Login\login_snake_game.py", line 82, in create_login_screen
    self.create_and_place_image_label(self.login_frame, 5, 635, self.config_path_icon)
  File "e:\Snake_game_V3\Snake_Game_V3\Login\login_snake_game.py", line 115, in create_and_place_image_label
    my_ctk_image = ctk.CTkImage(light_image=Image.open(my_image_with_rounded_corners))
                                            ^^^^^^^^^^^^^^^^^^^^^^^^^^^^^^^^^^^^^^^^^
  File "C:\Users\wimjr\AppData\Local\Programs\Python\Python311\Lib\site-packages\PIL\Image.py", line 3252, in open
    prefix = fp.read(16)
             ^^^^^^^
AttributeError: 'Image' object has no attribute 'read'
[2024-07-19 20:28:22] 


[2024-07-19 20:28:22] Started the Error Log File
[2024-07-19 20:28:48] No errors occurred
[2024-07-19 20:28:48] Closed the Error Log File




[2024-07-19 20:29:04] 


[2024-07-19 20:29:04] Started the Error Log File
[2024-07-19 20:51:55] No errors occurred
[2024-07-19 20:51:55] Closed the Error Log File




[2024-07-19 20:51:58] 


[2024-07-19 20:51:58] Started the Error Log File
Traceback (most recent call last):
  File "e:\Snake_game_V3\Snake_Game_V3\main_snake_game.py", line 1284, in <module>
    app = SnakeGameApp(root, GameConstants.MIN_WIDTH, GameConstants.MIN_HEIGHT)
          ^^^^^^^^^^^^^^^^^^^^^^^^^^^^^^^^^^^^^^^^^^^^^^^^^^^^^^^^^^^^^^^^^^^^^
  File "e:\Snake_game_V3\Snake_Game_V3\main_snake_game.py", line 261, in __init__
    self.create_login_screen_main()
  File "e:\Snake_game_V3\Snake_Game_V3\main_snake_game.py", line 269, in create_login_screen_main
    self.login_screen.create_login_screen()
  File "e:\Snake_game_V3\Snake_Game_V3\Login\login_snake_game.py", line 81, in create_login_screen
    self.login_label.pack(pady=10)
  File "C:\Users\wimjr\AppData\Local\Programs\Python\Python311\Lib\site-packages\customtkinter\windows\widgets\core_widget_classes\ctk_base_class.py", line 298, in pack
    return super().pack(**self._apply_argument_scaling(kwargs))
           ^^^^^^^^^^^^^^^^^^^^^^^^^^^^^^^^^^^^^^^^^^^^^^^^^^^^
  File "C:\Users\wimjr\AppData\Local\Programs\Python\Python311\Lib\tkinter\__init__.py", line 2452, in pack_configure
    self.tk.call(
_tkinter.TclError: cannot use geometry manager pack inside .!tabviewlogin which already has slaves managed by grid
[2024-07-19 21:01:42] 


[2024-07-19 21:01:42] Started the Error Log File
[2024-07-19 21:07:10] No errors occurred
[2024-07-19 21:07:10] Closed the Error Log File




[2024-07-19 21:07:16] 


[2024-07-19 21:07:16] Started the Error Log File
Traceback (most recent call last):
  File "e:\Snake_game_V3\Snake_Game_V3\main_snake_game.py", line 1284, in <module>
    app = SnakeGameApp(root, GameConstants.MIN_WIDTH, GameConstants.MIN_HEIGHT)
          ^^^^^^^^^^^^^^^^^^^^^^^^^^^^^^^^^^^^^^^^^^^^^^^^^^^^^^^^^^^^^^^^^^^^^
  File "e:\Snake_game_V3\Snake_Game_V3\main_snake_game.py", line 261, in __init__
    self.create_login_screen_main()
  File "e:\Snake_game_V3\Snake_Game_V3\main_snake_game.py", line 269, in create_login_screen_main
    self.login_screen.create_login_screen()
  File "e:\Snake_game_V3\Snake_Game_V3\Login\login_snake_game.py", line 89, in create_login_screen
    self.login_label.pack(pady=10)
  File "C:\Users\wimjr\AppData\Local\Programs\Python\Python311\Lib\site-packages\customtkinter\windows\widgets\core_widget_classes\ctk_base_class.py", line 298, in pack
    return super().pack(**self._apply_argument_scaling(kwargs))
           ^^^^^^^^^^^^^^^^^^^^^^^^^^^^^^^^^^^^^^^^^^^^^^^^^^^^
  File "C:\Users\wimjr\AppData\Local\Programs\Python\Python311\Lib\tkinter\__init__.py", line 2452, in pack_configure
    self.tk.call(
_tkinter.TclError: cannot use geometry manager pack inside .!mytabview which already has slaves managed by grid
[2024-07-19 21:13:19] 


[2024-07-19 21:13:19] Started the Error Log File
Traceback (most recent call last):
  File "e:\Snake_game_V3\Snake_Game_V3\main_snake_game.py", line 1284, in <module>
    app = SnakeGameApp(root, GameConstants.MIN_WIDTH, GameConstants.MIN_HEIGHT)
          ^^^^^^^^^^^^^^^^^^^^^^^^^^^^^^^^^^^^^^^^^^^^^^^^^^^^^^^^^^^^^^^^^^^^^
  File "e:\Snake_game_V3\Snake_Game_V3\main_snake_game.py", line 225, in __init__
    self.login_screen = LoginAndUserScreen(self.root, on_login_success_callback=self.show_loading_screen_after_login) # pylint: disable=line-too-long
                        ^^^^^^^^^^^^^^^^^^^^^^^^^^^^^^^^^^^^^^^^^^^^^^^^^^^^^^^^^^^^^^^^^^^^^^^^^^^^^^^^^^^^^^^^^^^^^
  File "e:\Snake_game_V3\Snake_Game_V3\Login\login_snake_game.py", line 43, in __init__
    self.add("tab pup")
  File "C:\Users\wimjr\AppData\Local\Programs\Python\Python311\Lib\site-packages\customtkinter\windows\widgets\ctk_tabview.py", line 360, in add
    return self.insert(len(self._tab_dict), name)
                           ^^^^^^^^^^^^^^
AttributeError: 'LoginAndUserScreen' object has no attribute '_tab_dict'
[2024-07-19 21:14:32] 


[2024-07-19 21:14:32] Started the Error Log File
[2024-07-19 21:14:45] No errors occurred
[2024-07-19 21:14:45] Closed the Error Log File




[2024-07-19 21:14:47] 


[2024-07-19 21:14:47] Started the Error Log File
[2024-07-19 21:15:44] No errors occurred
[2024-07-19 21:15:44] Closed the Error Log File




[2024-07-19 21:19:07] 


[2024-07-19 21:19:07] Started the Error Log File
[2024-07-19 21:20:09] No errors occurred
[2024-07-19 21:20:09] Closed the Error Log File




[2024-07-19 21:20:15] 


[2024-07-19 21:20:15] Started the Error Log File
[2024-07-19 21:38:18] No errors occurred
[2024-07-19 21:38:18] Closed the Error Log File




[2024-07-20 14:23:53] 


[2024-07-20 14:23:53] Started the Error Log File
Exception in Tkinter callback
Traceback (most recent call last):
  File "C:\Users\wimjr\AppData\Local\Programs\Python\Python311\Lib\tkinter\__init__.py", line 1948, in __call__
    return self.func(*args)
           ^^^^^^^^^^^^^^^^
  File "C:\Users\wimjr\AppData\Local\Programs\Python\Python311\Lib\site-packages\customtkinter\windows\widgets\core_widget_classes\dropdown_menu.py", line 101, in <lambda>
    command=lambda v=value: self._button_callback(v),
                            ^^^^^^^^^^^^^^^^^^^^^^^^
  File "C:\Users\wimjr\AppData\Local\Programs\Python\Python311\Lib\site-packages\customtkinter\windows\widgets\core_widget_classes\dropdown_menu.py", line 106, in _button_callback
    self._command(value)
  File "C:\Users\wimjr\AppData\Local\Programs\Python\Python311\Lib\site-packages\customtkinter\windows\widgets\ctk_combobox.py", line 384, in _dropdown_callback
    self._command(value)
TypeError: LoginAndUserScreen.update_usernames_combobox() takes 1 positional argument but 2 were given
[2024-07-20 14:24:56] No errors occurred
[2024-07-20 14:24:56] Closed the Error Log File




[2024-07-20 14:27:52] 


[2024-07-20 14:27:52] Started the Error Log File
Exception in Tkinter callback
Traceback (most recent call last):
  File "C:\Users\wimjr\AppData\Local\Programs\Python\Python311\Lib\tkinter\__init__.py", line 1948, in __call__
    return self.func(*args)
           ^^^^^^^^^^^^^^^^
  File "C:\Users\wimjr\AppData\Local\Programs\Python\Python311\Lib\site-packages\customtkinter\windows\widgets\core_widget_classes\dropdown_menu.py", line 101, in <lambda>
    command=lambda v=value: self._button_callback(v),
                            ^^^^^^^^^^^^^^^^^^^^^^^^
  File "C:\Users\wimjr\AppData\Local\Programs\Python\Python311\Lib\site-packages\customtkinter\windows\widgets\core_widget_classes\dropdown_menu.py", line 106, in _button_callback
    self._command(value)
  File "C:\Users\wimjr\AppData\Local\Programs\Python\Python311\Lib\site-packages\customtkinter\windows\widgets\ctk_combobox.py", line 384, in _dropdown_callback
    self._command(value)
TypeError: LoginAndUserScreen.update_usernames_combobox() takes 1 positional argument but 2 were given
[2024-07-20 14:29:22] No errors occurred
[2024-07-20 14:29:22] Closed the Error Log File




[2024-07-20 14:29:25] 


[2024-07-20 14:29:25] Started the Error Log File
Exception in Tkinter callback
Traceback (most recent call last):
  File "C:\Users\wimjr\AppData\Local\Programs\Python\Python311\Lib\tkinter\__init__.py", line 1948, in __call__
    return self.func(*args)
           ^^^^^^^^^^^^^^^^
  File "C:\Users\wimjr\AppData\Local\Programs\Python\Python311\Lib\site-packages\customtkinter\windows\widgets\core_widget_classes\dropdown_menu.py", line 101, in <lambda>
    command=lambda v=value: self._button_callback(v),
                            ^^^^^^^^^^^^^^^^^^^^^^^^
  File "C:\Users\wimjr\AppData\Local\Programs\Python\Python311\Lib\site-packages\customtkinter\windows\widgets\core_widget_classes\dropdown_menu.py", line 106, in _button_callback
    self._command(value)
  File "C:\Users\wimjr\AppData\Local\Programs\Python\Python311\Lib\site-packages\customtkinter\windows\widgets\ctk_combobox.py", line 384, in _dropdown_callback
    self._command(value)
TypeError: LoginAndUserScreen.update_usernames_combobox() takes 1 positional argument but 2 were given
[2024-07-20 14:29:51] No errors occurred
[2024-07-20 14:29:51] Closed the Error Log File




[2024-07-20 15:22:23] 


[2024-07-20 15:22:23] Started the Error Log File
Traceback (most recent call last):
  File "e:\Snake_game_V3\Snake_Game_V3\main_snake_game.py", line 1284, in <module>
    app = SnakeGameApp(root, GameConstants.MIN_WIDTH, GameConstants.MIN_HEIGHT)
          ^^^^^^^^^^^^^^^^^^^^^^^^^^^^^^^^^^^^^^^^^^^^^^^^^^^^^^^^^^^^^^^^^^^^^
  File "e:\Snake_game_V3\Snake_Game_V3\main_snake_game.py", line 227, in __init__
    self.create_button_panel = ClickButtonPanel(self.main_canvas, self.game_logger, self.functions) # pylint: disable=line-too-long
                               ^^^^^^^^^^^^^^^^^^^^^^^^^^^^^^^^^^^^^^^^^^^^^^^^^^^^^^^^^^^^^^^^^^^^
  File "e:\Snake_game_V3\Snake_Game_V3\Logic\buttonpanel_snake_game.py", line 131, in __init__
    self.parent.iconbitmap('app_icon.ico')
    ^^^^^^^^^^^^^^^^^^^^^^
AttributeError: 'CTkCanvas' object has no attribute 'iconbitmap'
[2024-07-20 15:29:27] 


[2024-07-20 15:29:27] Started the Error Log File
Exception in Tkinter callback
Traceback (most recent call last):
  File "C:\Users\wimjr\AppData\Local\Programs\Python\Python311\Lib\tkinter\__init__.py", line 1948, in __call__
    return self.func(*args)
           ^^^^^^^^^^^^^^^^
  File "C:\Users\wimjr\AppData\Local\Programs\Python\Python311\Lib\site-packages\customtkinter\windows\widgets\core_widget_classes\dropdown_menu.py", line 101, in <lambda>
    command=lambda v=value: self._button_callback(v),
                            ^^^^^^^^^^^^^^^^^^^^^^^^
  File "C:\Users\wimjr\AppData\Local\Programs\Python\Python311\Lib\site-packages\customtkinter\windows\widgets\core_widget_classes\dropdown_menu.py", line 106, in _button_callback
    self._command(value)
  File "C:\Users\wimjr\AppData\Local\Programs\Python\Python311\Lib\site-packages\customtkinter\windows\widgets\ctk_combobox.py", line 384, in _dropdown_callback
    self._command(value)
TypeError: LoginAndUserScreen.update_usernames_combobox() takes 1 positional argument but 2 were given
[2024-07-20 15:38:26] No errors occurred
[2024-07-20 15:38:26] Closed the Error Log File




[2024-07-20 15:38:34] 


[2024-07-20 15:38:34] Started the Error Log File
[2024-07-20 15:39:56] No errors occurred
[2024-07-20 15:39:56] Closed the Error Log File




[2024-07-20 15:39:58] 


[2024-07-20 15:39:58] Started the Error Log File
Exception in Tkinter callback
Traceback (most recent call last):
  File "C:\Users\wimjr\AppData\Local\Programs\Python\Python311\Lib\tkinter\__init__.py", line 1948, in __call__
    return self.func(*args)
           ^^^^^^^^^^^^^^^^
  File "C:\Users\wimjr\AppData\Local\Programs\Python\Python311\Lib\site-packages\customtkinter\windows\widgets\core_widget_classes\dropdown_menu.py", line 101, in <lambda>
    command=lambda v=value: self._button_callback(v),
                            ^^^^^^^^^^^^^^^^^^^^^^^^
  File "C:\Users\wimjr\AppData\Local\Programs\Python\Python311\Lib\site-packages\customtkinter\windows\widgets\core_widget_classes\dropdown_menu.py", line 106, in _button_callback
    self._command(value)
  File "C:\Users\wimjr\AppData\Local\Programs\Python\Python311\Lib\site-packages\customtkinter\windows\widgets\ctk_combobox.py", line 384, in _dropdown_callback
    self._command(value)
TypeError: LoginAndUserScreen.update_usernames_combobox() takes 1 positional argument but 2 were given
[2024-07-20 15:40:29] No errors occurred
[2024-07-20 15:40:29] Closed the Error Log File




[2024-07-20 15:40:54] 


[2024-07-20 15:40:54] Started the Error Log File
Exception in Tkinter callback
Traceback (most recent call last):
  File "C:\Users\wimjr\AppData\Local\Programs\Python\Python311\Lib\tkinter\__init__.py", line 1948, in __call__
    return self.func(*args)
           ^^^^^^^^^^^^^^^^
  File "C:\Users\wimjr\AppData\Local\Programs\Python\Python311\Lib\site-packages\customtkinter\windows\widgets\core_widget_classes\dropdown_menu.py", line 101, in <lambda>
    command=lambda v=value: self._button_callback(v),
                            ^^^^^^^^^^^^^^^^^^^^^^^^
  File "C:\Users\wimjr\AppData\Local\Programs\Python\Python311\Lib\site-packages\customtkinter\windows\widgets\core_widget_classes\dropdown_menu.py", line 106, in _button_callback
    self._command(value)
  File "C:\Users\wimjr\AppData\Local\Programs\Python\Python311\Lib\site-packages\customtkinter\windows\widgets\ctk_combobox.py", line 384, in _dropdown_callback
    self._command(value)
TypeError: LoginAndUserScreen.update_usernames_combobox() takes 1 positional argument but 2 were given
[2024-07-20 15:41:37] No errors occurred
[2024-07-20 15:41:37] Closed the Error Log File




[2024-07-20 15:41:41] 


[2024-07-20 15:41:41] Started the Error Log File
Exception in Tkinter callback
Traceback (most recent call last):
  File "C:\Users\wimjr\AppData\Local\Programs\Python\Python311\Lib\tkinter\__init__.py", line 1948, in __call__
    return self.func(*args)
           ^^^^^^^^^^^^^^^^
  File "C:\Users\wimjr\AppData\Local\Programs\Python\Python311\Lib\site-packages\customtkinter\windows\widgets\core_widget_classes\dropdown_menu.py", line 101, in <lambda>
    command=lambda v=value: self._button_callback(v),
                            ^^^^^^^^^^^^^^^^^^^^^^^^
  File "C:\Users\wimjr\AppData\Local\Programs\Python\Python311\Lib\site-packages\customtkinter\windows\widgets\core_widget_classes\dropdown_menu.py", line 106, in _button_callback
    self._command(value)
  File "C:\Users\wimjr\AppData\Local\Programs\Python\Python311\Lib\site-packages\customtkinter\windows\widgets\ctk_combobox.py", line 384, in _dropdown_callback
    self._command(value)
TypeError: LoginAndUserScreen.update_usernames_combobox() takes 1 positional argument but 2 were given
[2024-07-20 15:42:09] No errors occurred
[2024-07-20 15:42:09] Closed the Error Log File




[2024-07-20 15:42:11] 


[2024-07-20 15:42:11] Started the Error Log File
Exception in Tkinter callback
Traceback (most recent call last):
  File "C:\Users\wimjr\AppData\Local\Programs\Python\Python311\Lib\tkinter\__init__.py", line 1948, in __call__
    return self.func(*args)
           ^^^^^^^^^^^^^^^^
  File "C:\Users\wimjr\AppData\Local\Programs\Python\Python311\Lib\site-packages\customtkinter\windows\widgets\core_widget_classes\dropdown_menu.py", line 101, in <lambda>
    command=lambda v=value: self._button_callback(v),
                            ^^^^^^^^^^^^^^^^^^^^^^^^
  File "C:\Users\wimjr\AppData\Local\Programs\Python\Python311\Lib\site-packages\customtkinter\windows\widgets\core_widget_classes\dropdown_menu.py", line 106, in _button_callback
    self._command(value)
  File "C:\Users\wimjr\AppData\Local\Programs\Python\Python311\Lib\site-packages\customtkinter\windows\widgets\ctk_combobox.py", line 384, in _dropdown_callback
    self._command(value)
TypeError: LoginAndUserScreen.update_usernames_combobox() takes 1 positional argument but 2 were given
[2024-07-20 15:42:27] No errors occurred
[2024-07-20 15:42:27] Closed the Error Log File




[2024-07-20 15:43:40] 


[2024-07-20 15:43:40] Started the Error Log File
Traceback (most recent call last):
  File "e:\Snake_game_V3\Snake_Game_V3\main_snake_game.py", line 1285, in <module>
    app = SnakeGameApp(root, GameConstants.MIN_WIDTH, GameConstants.MIN_HEIGHT)
          ^^^^^^^^^^^^^^^^^^^^^^^^^^^^^^^^^^^^^^^^^^^^^^^^^^^^^^^^^^^^^^^^^^^^^
  File "e:\Snake_game_V3\Snake_Game_V3\main_snake_game.py", line 227, in __init__
    self.create_button_panel = ClickButtonPanel(self.main_canvas, self.game_logger, self.functions) # pylint: disable=line-too-long
                               ^^^^^^^^^^^^^^^^^^^^^^^^^^^^^^^^^^^^^^^^^^^^^^^^^^^^^^^^^^^^^^^^^^^^
  File "e:\Snake_game_V3\Snake_Game_V3\Logic\buttonpanel_snake_game.py", line 127, in __init__
    self.create_and_place_image_label(self.button_canvas, 10, 10, 'Images/ShadowSnakeLogo.png')
  File "e:\Snake_game_V3\Snake_Game_V3\Logic\buttonpanel_snake_game.py", line 133, in create_and_place_image_label
    my_image = ctk.CTkImage(light_image=Image.open(image_path),
                                        ^^^^^^^^^^^^^^^^^^^^^^
  File "C:\Users\wimjr\AppData\Local\Programs\Python\Python311\Lib\site-packages\PIL\Image.py", line 3243, in open
    fp = builtins.open(filename, "rb")
         ^^^^^^^^^^^^^^^^^^^^^^^^^^^^^
FileNotFoundError: [Errno 2] No such file or directory: 'Images/ShadowSnakeLogo.png'
[2024-07-20 15:45:06] 


[2024-07-20 15:45:06] Started the Error Log File
Traceback (most recent call last):
  File "e:\Snake_game_V3\Snake_Game_V3\main_snake_game.py", line 1285, in <module>
    app = SnakeGameApp(root, GameConstants.MIN_WIDTH, GameConstants.MIN_HEIGHT)
          ^^^^^^^^^^^^^^^^^^^^^^^^^^^^^^^^^^^^^^^^^^^^^^^^^^^^^^^^^^^^^^^^^^^^^
  File "e:\Snake_game_V3\Snake_Game_V3\main_snake_game.py", line 227, in __init__
    self.create_button_panel = ClickButtonPanel(self.main_canvas, self.game_logger, self.functions) # pylint: disable=line-too-long
                               ^^^^^^^^^^^^^^^^^^^^^^^^^^^^^^^^^^^^^^^^^^^^^^^^^^^^^^^^^^^^^^^^^^^^
  File "e:\Snake_game_V3\Snake_Game_V3\Logic\buttonpanel_snake_game.py", line 132, in __init__
    self.create_and_place_image_label(self.button_canvas, 10, 10, self.config_path_icon)
  File "e:\Snake_game_V3\Snake_Game_V3\Logic\buttonpanel_snake_game.py", line 138, in create_and_place_image_label
    my_image = ctk.CTkImage(light_image=Image.open(image_path),
                                        ^^^^^^^^^^^^^^^^^^^^^^
  File "C:\Users\wimjr\AppData\Local\Programs\Python\Python311\Lib\site-packages\PIL\Image.py", line 3243, in open
    fp = builtins.open(filename, "rb")
         ^^^^^^^^^^^^^^^^^^^^^^^^^^^^^
FileNotFoundError: [Errno 2] No such file or directory: 'e:\\Snake_game_V3\\Snake_Game_V3\\Logic\\app_icon.ico'
[2024-07-20 15:45:10] 


[2024-07-20 15:45:10] Started the Error Log File
Traceback (most recent call last):
  File "e:\Snake_game_V3\Snake_Game_V3\main_snake_game.py", line 1285, in <module>
    app = SnakeGameApp(root, GameConstants.MIN_WIDTH, GameConstants.MIN_HEIGHT)
          ^^^^^^^^^^^^^^^^^^^^^^^^^^^^^^^^^^^^^^^^^^^^^^^^^^^^^^^^^^^^^^^^^^^^^
  File "e:\Snake_game_V3\Snake_Game_V3\main_snake_game.py", line 227, in __init__
    self.create_button_panel = ClickButtonPanel(self.main_canvas, self.game_logger, self.functions) # pylint: disable=line-too-long
                               ^^^^^^^^^^^^^^^^^^^^^^^^^^^^^^^^^^^^^^^^^^^^^^^^^^^^^^^^^^^^^^^^^^^^
  File "e:\Snake_game_V3\Snake_Game_V3\Logic\buttonpanel_snake_game.py", line 132, in __init__
    self.create_and_place_image_label(self.button_canvas, 10, 10, self.config_path_icon)
  File "e:\Snake_game_V3\Snake_Game_V3\Logic\buttonpanel_snake_game.py", line 138, in create_and_place_image_label
    my_image = ctk.CTkImage(light_image=Image.open(image_path),
                                        ^^^^^^^^^^^^^^^^^^^^^^
  File "C:\Users\wimjr\AppData\Local\Programs\Python\Python311\Lib\site-packages\PIL\Image.py", line 3243, in open
    fp = builtins.open(filename, "rb")
         ^^^^^^^^^^^^^^^^^^^^^^^^^^^^^
FileNotFoundError: [Errno 2] No such file or directory: 'e:\\Snake_game_V3\\Snake_Game_V3\\Logic\\app_icon.ico'
[2024-07-20 15:45:38] 


[2024-07-20 15:45:38] Started the Error Log File
Exception in Tkinter callback
Traceback (most recent call last):
  File "C:\Users\wimjr\AppData\Local\Programs\Python\Python311\Lib\tkinter\__init__.py", line 1948, in __call__
    return self.func(*args)
           ^^^^^^^^^^^^^^^^
  File "C:\Users\wimjr\AppData\Local\Programs\Python\Python311\Lib\site-packages\customtkinter\windows\widgets\core_widget_classes\dropdown_menu.py", line 101, in <lambda>
    command=lambda v=value: self._button_callback(v),
                            ^^^^^^^^^^^^^^^^^^^^^^^^
  File "C:\Users\wimjr\AppData\Local\Programs\Python\Python311\Lib\site-packages\customtkinter\windows\widgets\core_widget_classes\dropdown_menu.py", line 106, in _button_callback
    self._command(value)
  File "C:\Users\wimjr\AppData\Local\Programs\Python\Python311\Lib\site-packages\customtkinter\windows\widgets\ctk_combobox.py", line 384, in _dropdown_callback
    self._command(value)
TypeError: LoginAndUserScreen.update_usernames_combobox() takes 1 positional argument but 2 were given
[2024-07-20 15:46:40] No errors occurred
[2024-07-20 15:46:40] Closed the Error Log File




[2024-07-20 15:46:43] 


[2024-07-20 15:46:43] Started the Error Log File
Exception in Tkinter callback
Traceback (most recent call last):
  File "C:\Users\wimjr\AppData\Local\Programs\Python\Python311\Lib\tkinter\__init__.py", line 1948, in __call__
    return self.func(*args)
           ^^^^^^^^^^^^^^^^
  File "C:\Users\wimjr\AppData\Local\Programs\Python\Python311\Lib\site-packages\customtkinter\windows\widgets\core_widget_classes\dropdown_menu.py", line 101, in <lambda>
    command=lambda v=value: self._button_callback(v),
                            ^^^^^^^^^^^^^^^^^^^^^^^^
  File "C:\Users\wimjr\AppData\Local\Programs\Python\Python311\Lib\site-packages\customtkinter\windows\widgets\core_widget_classes\dropdown_menu.py", line 106, in _button_callback
    self._command(value)
  File "C:\Users\wimjr\AppData\Local\Programs\Python\Python311\Lib\site-packages\customtkinter\windows\widgets\ctk_combobox.py", line 384, in _dropdown_callback
    self._command(value)
TypeError: LoginAndUserScreen.update_usernames_combobox() takes 1 positional argument but 2 were given
Exception in Tkinter callback
Traceback (most recent call last):
  File "C:\Users\wimjr\AppData\Local\Programs\Python\Python311\Lib\tkinter\__init__.py", line 1948, in __call__
    return self.func(*args)
           ^^^^^^^^^^^^^^^^
  File "C:\Users\wimjr\AppData\Local\Programs\Python\Python311\Lib\site-packages\customtkinter\windows\widgets\ctk_button.py", line 554, in _clicked
    self._command()
  File "e:\Snake_game_V3\Snake_Game_V3\Logic\button_commands_snake_game.py", line 68, in info_command
    self.functions['open_info']()
  File "e:\Snake_game_V3\Snake_Game_V3\main_snake_game.py", line 500, in open_info
    self.start_game("info")
  File "e:\Snake_game_V3\Snake_Game_V3\main_snake_game.py", line 757, in start_game
    self.create_button_panel.create_patchnotes_button()
  File "e:\Snake_game_V3\Snake_Game_V3\Logic\buttonpanel_snake_game.py", line 440, in create_patchnotes_button
    patchnotes_button = ctk.CTkButton(self.button_canvas, text="Patchnotes", font=FONT_LIST[11], # pylint: disable=line-too-long
                        ^^^^^^^^^^^^^^^^^^^^^^^^^^^^^^^^^^^^^^^^^^^^^^^^^^^^^^^^^^^^^^^^^^^^^^^^^^^^^^^^^^^^^^^^^^^^^^^^^^^^^^^^
  File "C:\Users\wimjr\AppData\Local\Programs\Python\Python311\Lib\site-packages\customtkinter\windows\widgets\ctk_button.py", line 52, in __init__
    super().__init__(master=master, bg_color=bg_color, width=width, height=height, **kwargs)
  File "C:\Users\wimjr\AppData\Local\Programs\Python\Python311\Lib\site-packages\customtkinter\windows\widgets\core_widget_classes\ctk_base_class.py", line 41, in __init__
    tkinter.Frame.__init__(self, master=master, width=width, height=height, **pop_from_dict_by_set(kwargs, self._valid_tk_frame_attributes))
  File "C:\Users\wimjr\AppData\Local\Programs\Python\Python311\Lib\tkinter\__init__.py", line 3190, in __init__
    Widget.__init__(self, master, 'frame', cnf, {}, extra)
  File "C:\Users\wimjr\AppData\Local\Programs\Python\Python311\Lib\tkinter\__init__.py", line 2628, in __init__
    self.tk.call(
_tkinter.TclError: bad window path name ".!ctkcanvas6"
[2024-07-20 15:48:01] No errors occurred
[2024-07-20 15:48:01] Closed the Error Log File




[2024-07-21 11:05:16] 


[2024-07-21 11:05:16] Started the Error Log File
[2024-07-21 11:07:26] No errors occurred
[2024-07-21 11:07:26] Closed the Error Log File




[2024-07-21 11:07:28] 


[2024-07-21 11:07:28] Started the Error Log File
Exception in Tkinter callback
Traceback (most recent call last):
  File "C:\Users\wimjr\AppData\Local\Programs\Python\Python311\Lib\tkinter\__init__.py", line 1948, in __call__
    return self.func(*args)
           ^^^^^^^^^^^^^^^^
  File "C:\Users\wimjr\AppData\Local\Programs\Python\Python311\Lib\site-packages\customtkinter\windows\widgets\ctk_button.py", line 554, in _clicked
    self._command()
  File "e:\Snake_game_V3\Snake_Game_V3\Login\login_snake_game.py", line 214, in login
    username = self.username_entry.get()
               ^^^^^^^^^^^^^^^^^^^^^^^
AttributeError: 'NoneType' object has no attribute 'get'
[2024-07-21 11:09:16] No errors occurred
[2024-07-21 11:09:16] Closed the Error Log File




[2024-07-21 11:09:17] 


[2024-07-21 11:09:17] Started the Error Log File
Exception in Tkinter callback
Traceback (most recent call last):
  File "C:\Users\wimjr\AppData\Local\Programs\Python\Python311\Lib\tkinter\__init__.py", line 1948, in __call__
    return self.func(*args)
           ^^^^^^^^^^^^^^^^
  File "C:\Users\wimjr\AppData\Local\Programs\Python\Python311\Lib\site-packages\customtkinter\windows\widgets\ctk_button.py", line 554, in _clicked
    self._command()
  File "e:\Snake_game_V3\Snake_Game_V3\Login\login_snake_game.py", line 234, in login
    self.result_label.configure(text="Please enter a username and password", fg_color="red")
    ^^^^^^^^^^^^^^^^^^^^^^^^^^^
AttributeError: 'NoneType' object has no attribute 'configure'
Exception in Tkinter callback
Traceback (most recent call last):
  File "C:\Users\wimjr\AppData\Local\Programs\Python\Python311\Lib\tkinter\__init__.py", line 1948, in __call__
    return self.func(*args)
           ^^^^^^^^^^^^^^^^
  File "C:\Users\wimjr\AppData\Local\Programs\Python\Python311\Lib\site-packages\customtkinter\windows\widgets\ctk_button.py", line 554, in _clicked
    self._command()
  File "e:\Snake_game_V3\Snake_Game_V3\Login\login_snake_game.py", line 221, in login
    self.result_label.configure(text="Login successful!", fg_color="green")
    ^^^^^^^^^^^^^^^^^^^^^^^^^^^
AttributeError: 'NoneType' object has no attribute 'configure'
[2024-07-21 11:09:47] No errors occurred
[2024-07-21 11:09:47] Closed the Error Log File




[2024-07-21 11:10:18] 


[2024-07-21 11:10:18] Started the Error Log File
[2024-07-21 11:10:25] No errors occurred
[2024-07-21 11:10:25] Closed the Error Log File




[2024-07-21 11:10:30] 


[2024-07-21 11:10:30] Started the Error Log File
[2024-07-21 11:11:09] No errors occurred
[2024-07-21 11:11:09] Closed the Error Log File




[2024-07-21 11:11:11] 


[2024-07-21 11:11:11] Started the Error Log File
[2024-07-21 11:11:23] No errors occurred
[2024-07-21 11:11:23] Closed the Error Log File




[2024-07-21 11:17:51] 


[2024-07-21 11:17:51] Started the Error Log File
[2024-07-21 11:19:41] No errors occurred
[2024-07-21 11:19:41] Closed the Error Log File




[2024-07-21 11:19:44] 


[2024-07-21 11:19:44] Started the Error Log File
[2024-07-21 11:23:23] No errors occurred
[2024-07-21 11:23:23] Closed the Error Log File




[2024-07-21 11:23:26] 


[2024-07-21 11:23:26] Started the Error Log File
[2024-07-21 11:24:16] No errors occurred
[2024-07-21 11:24:16] Closed the Error Log File




[2024-07-21 11:24:18] 


[2024-07-21 11:24:18] Started the Error Log File
[2024-07-21 11:28:50] No errors occurred
[2024-07-21 11:28:50] Closed the Error Log File




[2024-07-21 11:28:53] 


[2024-07-21 11:28:53] Started the Error Log File
[2024-07-21 11:29:02] No errors occurred
[2024-07-21 11:29:02] Closed the Error Log File




[2024-07-21 11:31:02] 


[2024-07-21 11:31:02] Started the Error Log File
[2024-07-21 11:31:18] No errors occurred
[2024-07-21 11:31:18] Closed the Error Log File




[2024-07-21 11:34:37] 


[2024-07-21 11:34:37] Started the Error Log File
[2024-07-21 11:34:38] No errors occurred
[2024-07-21 11:34:38] Closed the Error Log File




[2024-07-21 11:35:24] 


[2024-07-21 11:35:24] Started the Error Log File
[2024-07-21 11:35:26] No errors occurred
[2024-07-21 11:35:26] Closed the Error Log File




[2024-07-21 11:44:21] 


[2024-07-21 11:44:21] Started the Error Log File
[2024-07-21 11:44:40] No errors occurred
[2024-07-21 11:44:40] Closed the Error Log File




[2024-07-21 11:44:43] 


[2024-07-21 11:44:43] Started the Error Log File
[2024-07-21 11:45:54] No errors occurred
[2024-07-21 11:45:54] Closed the Error Log File




[2024-07-21 11:45:56] 


[2024-07-21 11:45:56] Started the Error Log File
[2024-07-21 11:47:04] No errors occurred
[2024-07-21 11:47:04] Closed the Error Log File




[2024-07-21 11:47:06] 


[2024-07-21 11:47:06] Started the Error Log File
[2024-07-21 11:47:48] No errors occurred
[2024-07-21 11:47:48] Closed the Error Log File




[2024-07-21 11:47:49] 


[2024-07-21 11:47:49] Started the Error Log File
[2024-07-21 11:48:05] No errors occurred
[2024-07-21 11:48:05] Closed the Error Log File




[2024-07-21 11:48:07] 


[2024-07-21 11:48:07] Started the Error Log File
[2024-07-21 11:48:35] No errors occurred
[2024-07-21 11:48:35] Closed the Error Log File




[2024-07-21 11:48:37] 


[2024-07-21 11:48:37] Started the Error Log File
[2024-07-21 11:50:14] No errors occurred
[2024-07-21 11:50:14] Closed the Error Log File




[2024-07-21 11:50:16] 


[2024-07-21 11:50:16] Started the Error Log File
[2024-07-21 11:52:06] No errors occurred
[2024-07-21 11:52:06] Closed the Error Log File




[2024-07-21 11:52:30] 


[2024-07-21 11:52:30] Started the Error Log File
[2024-07-21 11:56:54] No errors occurred
[2024-07-21 11:56:54] Closed the Error Log File




[2024-07-21 11:56:56] 


[2024-07-21 11:56:56] Started the Error Log File
[2024-07-21 11:57:07] No errors occurred
[2024-07-21 11:57:07] Closed the Error Log File




[2024-07-21 11:57:09] 


[2024-07-21 11:57:09] Started the Error Log File
[2024-07-21 11:57:21] No errors occurred
[2024-07-21 11:57:21] Closed the Error Log File




[2024-07-21 11:57:24] 


[2024-07-21 11:57:24] Started the Error Log File
[2024-07-21 11:57:45] No errors occurred
[2024-07-21 11:57:45] Closed the Error Log File




[2024-07-21 11:57:47] 


[2024-07-21 11:57:47] Started the Error Log File
[2024-07-21 11:58:05] No errors occurred
[2024-07-21 11:58:05] Closed the Error Log File




[2024-07-21 11:58:18] 


[2024-07-21 11:58:18] Started the Error Log File
[2024-07-21 12:00:05] No errors occurred
[2024-07-21 12:00:05] Closed the Error Log File




[2024-07-21 12:50:00] 


[2024-07-21 12:50:00] Started the Error Log File
[2024-07-21 12:53:26] No errors occurred
[2024-07-21 12:53:26] Closed the Error Log File




[2024-07-21 12:53:30] 


[2024-07-21 12:53:30] Started the Error Log File
Exception in Tkinter callback
Traceback (most recent call last):
  File "C:\Users\wimjr\AppData\Local\Programs\Python\Python311\Lib\tkinter\__init__.py", line 1948, in __call__
    return self.func(*args)
           ^^^^^^^^^^^^^^^^
  File "C:\Users\wimjr\AppData\Local\Programs\Python\Python311\Lib\site-packages\customtkinter\windows\widgets\ctk_button.py", line 554, in _clicked
    self._command()
  File "e:\Snake_game_V3\Snake_Game_V3\Login\login_snake_game.py", line 215, in create_user
    username = self.username_entry.get()
               ^^^^^^^^^^^^^^^^^^^^^^^^^
  File "C:\Users\wimjr\AppData\Local\Programs\Python\Python311\Lib\site-packages\customtkinter\windows\widgets\ctk_entry.py", line 342, in get
    return self._entry.get()
           ^^^^^^^^^^^^^^^^^
  File "C:\Users\wimjr\AppData\Local\Programs\Python\Python311\Lib\tkinter\__init__.py", line 3109, in get
    return self.tk.call(self._w, 'get')
           ^^^^^^^^^^^^^^^^^^^^^^^^^^^^
_tkinter.TclError: invalid command name ".!ctkframe2.!ctkframe2.!ctkentry.!entry"
[2024-07-21 12:54:56] No errors occurred
[2024-07-21 12:54:56] Closed the Error Log File




[2024-07-21 12:55:02] 


[2024-07-21 12:55:02] Started the Error Log File
[2024-07-21 12:55:29] No errors occurred
[2024-07-21 12:55:29] Closed the Error Log File




[2024-07-21 12:55:50] 


[2024-07-21 12:55:50] Started the Error Log File
[2024-07-21 13:00:52] No errors occurred
[2024-07-21 13:00:52] Closed the Error Log File




[2024-07-21 13:00:54] 


[2024-07-21 13:00:54] Started the Error Log File
[2024-07-21 13:01:49] No errors occurred
[2024-07-21 13:01:49] Closed the Error Log File




[2024-07-21 13:01:51] 


[2024-07-21 13:01:51] Started the Error Log File
[2024-07-21 13:02:04] No errors occurred
[2024-07-21 13:02:04] Closed the Error Log File




[2024-07-21 13:02:06] 


[2024-07-21 13:02:06] Started the Error Log File
[2024-07-21 13:02:19] No errors occurred
[2024-07-21 13:02:19] Closed the Error Log File




[2024-07-21 13:02:32] 


[2024-07-21 13:02:32] Started the Error Log File
[2024-07-21 13:03:23] No errors occurred
[2024-07-21 13:03:23] Closed the Error Log File




[2024-07-21 13:03:26] 


[2024-07-21 13:03:26] Started the Error Log File
[2024-07-21 13:05:21] No errors occurred
[2024-07-21 13:05:21] Closed the Error Log File




[2024-07-21 13:05:23] 


[2024-07-21 13:05:23] Started the Error Log File
[2024-07-21 13:09:24] No errors occurred
[2024-07-21 13:09:24] Closed the Error Log File




[2024-07-21 13:09:27] 


[2024-07-21 13:09:27] Started the Error Log File
[2024-07-21 13:11:15] No errors occurred
[2024-07-21 13:11:15] Closed the Error Log File




[2024-07-21 13:11:17] 


[2024-07-21 13:11:17] Started the Error Log File
[2024-07-21 13:12:27] No errors occurred
[2024-07-21 13:12:27] Closed the Error Log File




[2024-07-21 13:12:30] 


[2024-07-21 13:12:30] Started the Error Log File
[2024-07-21 13:12:44] No errors occurred
[2024-07-21 13:12:44] Closed the Error Log File




[2024-07-21 13:12:46] 


[2024-07-21 13:12:46] Started the Error Log File
[2024-07-21 13:16:08] No errors occurred
[2024-07-21 13:16:08] Closed the Error Log File




[2024-07-21 13:16:15] 


[2024-07-21 13:16:15] Started the Error Log File
[2024-07-21 13:18:05] No errors occurred
[2024-07-21 13:18:05] Closed the Error Log File




[2024-07-21 13:18:11] 


[2024-07-21 13:18:11] Started the Error Log File
[2024-07-21 13:27:40] No errors occurred
[2024-07-21 13:27:40] Closed the Error Log File




[2024-07-21 13:27:43] 


[2024-07-21 13:27:43] Started the Error Log File
[2024-07-21 13:28:39] No errors occurred
[2024-07-21 13:28:39] Closed the Error Log File




[2024-07-21 13:28:41] 


[2024-07-21 13:28:41] Started the Error Log File
[2024-07-21 13:31:31] No errors occurred
[2024-07-21 13:31:31] Closed the Error Log File




[2024-07-21 13:31:33] 


[2024-07-21 13:31:33] Started the Error Log File
[2024-07-21 13:37:23] No errors occurred
[2024-07-21 13:37:23] Closed the Error Log File




[2024-07-21 13:37:25] 


[2024-07-21 13:37:25] Started the Error Log File
[2024-07-21 13:44:16] No errors occurred
[2024-07-21 13:44:16] Closed the Error Log File




[2024-07-21 13:44:18] 


[2024-07-21 13:44:18] Started the Error Log File
[2024-07-21 13:44:48] No errors occurred
[2024-07-21 13:44:48] Closed the Error Log File




[2024-07-21 13:44:51] 


[2024-07-21 13:44:51] Started the Error Log File
[2024-07-21 13:45:13] No errors occurred
[2024-07-21 13:45:13] Closed the Error Log File




[2024-07-21 13:45:29] 


[2024-07-21 13:45:29] Started the Error Log File
[2024-07-21 13:46:01] No errors occurred
[2024-07-21 13:46:01] Closed the Error Log File




[2024-07-21 13:46:02] 


[2024-07-21 13:46:02] Started the Error Log File
[2024-07-21 13:46:29] No errors occurred
[2024-07-21 13:46:29] Closed the Error Log File




[2024-07-21 13:52:44] 


[2024-07-21 13:52:44] Started the Error Log File
[2024-07-21 13:53:10] No errors occurred
[2024-07-21 13:53:10] Closed the Error Log File




[2024-07-21 13:53:19] 


[2024-07-21 13:53:19] Started the Error Log File
[2024-07-21 14:04:04] No errors occurred
[2024-07-21 14:04:04] Closed the Error Log File




[2024-07-21 14:04:06] 


[2024-07-21 14:04:06] Started the Error Log File
Exception in Tkinter callback
Traceback (most recent call last):
  File "C:\Users\wimjr\AppData\Local\Programs\Python\Python311\Lib\tkinter\__init__.py", line 1948, in __call__
    return self.func(*args)
           ^^^^^^^^^^^^^^^^
  File "C:\Users\wimjr\AppData\Local\Programs\Python\Python311\Lib\site-packages\customtkinter\windows\widgets\ctk_button.py", line 554, in _clicked
    self._command()
  File "e:\Snake_game_V3\Snake_Game_V3\Login\login_snake_game.py", line 296, in forgot_password_callback
    username = self.username_forgot_password_entry.get()
               ^^^^^^^^^^^^^^^^^^^^^^^^^^^^^^^^^^^
AttributeError: 'LoginAndUserScreen' object has no attribute 'username_forgot_password_entry'
Exception in Tkinter callback
Traceback (most recent call last):
  File "C:\Users\wimjr\AppData\Local\Programs\Python\Python311\Lib\tkinter\__init__.py", line 1948, in __call__
    return self.func(*args)
           ^^^^^^^^^^^^^^^^
  File "C:\Users\wimjr\AppData\Local\Programs\Python\Python311\Lib\site-packages\customtkinter\windows\widgets\ctk_button.py", line 554, in _clicked
    self._command()
  File "e:\Snake_game_V3\Snake_Game_V3\Login\login_snake_game.py", line 324, in delete_forgot_password_widgets
    self.instruction_label.destroy()
    ^^^^^^^^^^^^^^^^^^^^^^
AttributeError: 'LoginAndUserScreen' object has no attribute 'instruction_label'
[2024-07-21 14:09:29] No errors occurred
[2024-07-21 14:09:29] Closed the Error Log File




[2024-07-21 14:09:35] 


[2024-07-21 14:09:35] Started the Error Log File
[2024-07-21 14:30:52] No errors occurred
[2024-07-21 14:30:52] Closed the Error Log File




[2024-07-21 14:31:01] 


[2024-07-21 14:31:01] Started the Error Log File
[2024-07-21 14:41:10] No errors occurred
[2024-07-21 14:41:10] Closed the Error Log File




[2024-07-21 14:41:13] 


[2024-07-21 14:41:13] Started the Error Log File
[2024-07-21 14:42:01] No errors occurred
[2024-07-21 14:42:01] Closed the Error Log File




[2024-07-21 14:42:07] 


[2024-07-21 14:42:07] Started the Error Log File
Exception in Tkinter callback
Traceback (most recent call last):
  File "C:\Users\wimjr\AppData\Local\Programs\Python\Python311\Lib\tkinter\__init__.py", line 1948, in __call__
    return self.func(*args)
           ^^^^^^^^^^^^^^^^
  File "C:\Users\wimjr\AppData\Local\Programs\Python\Python311\Lib\site-packages\customtkinter\windows\widgets\ctk_button.py", line 554, in _clicked
    self._command()
TypeError: LoginAndUserScreen.confirm_delete_user() missing 3 required positional arguments: 'username', 'password', and 'users'
Exception in Tkinter callback
Traceback (most recent call last):
  File "C:\Users\wimjr\AppData\Local\Programs\Python\Python311\Lib\tkinter\__init__.py", line 1948, in __call__
    return self.func(*args)
           ^^^^^^^^^^^^^^^^
  File "C:\Users\wimjr\AppData\Local\Programs\Python\Python311\Lib\site-packages\customtkinter\windows\widgets\ctk_button.py", line 554, in _clicked
    self._command()
TypeError: LoginAndUserScreen.confirm_delete_user() missing 3 required positional arguments: 'username', 'password', and 'users'
Exception in Tkinter callback
Traceback (most recent call last):
  File "C:\Users\wimjr\AppData\Local\Programs\Python\Python311\Lib\tkinter\__init__.py", line 1948, in __call__
    return self.func(*args)
           ^^^^^^^^^^^^^^^^
  File "C:\Users\wimjr\AppData\Local\Programs\Python\Python311\Lib\site-packages\customtkinter\windows\widgets\ctk_button.py", line 554, in _clicked
    self._command()
TypeError: LoginAndUserScreen.confirm_delete_user() missing 3 required positional arguments: 'username', 'password', and 'users'
Exception in Tkinter callback
Traceback (most recent call last):
  File "C:\Users\wimjr\AppData\Local\Programs\Python\Python311\Lib\tkinter\__init__.py", line 1948, in __call__
    return self.func(*args)
           ^^^^^^^^^^^^^^^^
  File "C:\Users\wimjr\AppData\Local\Programs\Python\Python311\Lib\site-packages\customtkinter\windows\widgets\ctk_button.py", line 554, in _clicked
    self._command()
TypeError: LoginAndUserScreen.confirm_delete_user() missing 3 required positional arguments: 'username', 'password', and 'users'
Exception in Tkinter callback
Traceback (most recent call last):
  File "C:\Users\wimjr\AppData\Local\Programs\Python\Python311\Lib\tkinter\__init__.py", line 1948, in __call__
    return self.func(*args)
           ^^^^^^^^^^^^^^^^
  File "C:\Users\wimjr\AppData\Local\Programs\Python\Python311\Lib\site-packages\customtkinter\windows\widgets\ctk_button.py", line 554, in _clicked
    self._command()
TypeError: LoginAndUserScreen.confirm_delete_user() missing 3 required positional arguments: 'username', 'password', and 'users'
[2024-07-21 14:43:17] No errors occurred
[2024-07-21 14:43:17] Closed the Error Log File




[2024-07-21 14:43:23] 


[2024-07-21 14:43:23] Started the Error Log File
Exception in Tkinter callback
Traceback (most recent call last):
  File "C:\Users\wimjr\AppData\Local\Programs\Python\Python311\Lib\tkinter\__init__.py", line 1948, in __call__
    return self.func(*args)
           ^^^^^^^^^^^^^^^^
  File "C:\Users\wimjr\AppData\Local\Programs\Python\Python311\Lib\site-packages\customtkinter\windows\widgets\ctk_button.py", line 554, in _clicked
    self._command()
TypeError: LoginAndUserScreen.confirm_delete_user() missing 3 required positional arguments: 'username', 'password', and 'users'
Exception in Tkinter callback
Traceback (most recent call last):
  File "C:\Users\wimjr\AppData\Local\Programs\Python\Python311\Lib\tkinter\__init__.py", line 1948, in __call__
    return self.func(*args)
           ^^^^^^^^^^^^^^^^
  File "C:\Users\wimjr\AppData\Local\Programs\Python\Python311\Lib\site-packages\customtkinter\windows\widgets\ctk_button.py", line 554, in _clicked
    self._command()
TypeError: LoginAndUserScreen.confirm_delete_user() missing 3 required positional arguments: 'username', 'password', and 'users'
Exception in Tkinter callback
Traceback (most recent call last):
  File "C:\Users\wimjr\AppData\Local\Programs\Python\Python311\Lib\tkinter\__init__.py", line 1948, in __call__
    return self.func(*args)
           ^^^^^^^^^^^^^^^^
  File "C:\Users\wimjr\AppData\Local\Programs\Python\Python311\Lib\site-packages\customtkinter\windows\widgets\ctk_button.py", line 554, in _clicked
    self._command()
TypeError: LoginAndUserScreen.confirm_delete_user() missing 3 required positional arguments: 'username', 'password', and 'users'
Exception in Tkinter callback
Traceback (most recent call last):
  File "C:\Users\wimjr\AppData\Local\Programs\Python\Python311\Lib\tkinter\__init__.py", line 1948, in __call__
    return self.func(*args)
           ^^^^^^^^^^^^^^^^
  File "C:\Users\wimjr\AppData\Local\Programs\Python\Python311\Lib\site-packages\customtkinter\windows\widgets\ctk_button.py", line 554, in _clicked
    self._command()
TypeError: LoginAndUserScreen.confirm_delete_user() missing 3 required positional arguments: 'username', 'password', and 'users'
Exception in Tkinter callback
Traceback (most recent call last):
  File "C:\Users\wimjr\AppData\Local\Programs\Python\Python311\Lib\tkinter\__init__.py", line 1948, in __call__
    return self.func(*args)
           ^^^^^^^^^^^^^^^^
  File "C:\Users\wimjr\AppData\Local\Programs\Python\Python311\Lib\site-packages\customtkinter\windows\widgets\ctk_button.py", line 554, in _clicked
    self._command()
TypeError: LoginAndUserScreen.confirm_delete_user() missing 3 required positional arguments: 'username', 'password', and 'users'
Exception in Tkinter callback
Traceback (most recent call last):
  File "C:\Users\wimjr\AppData\Local\Programs\Python\Python311\Lib\tkinter\__init__.py", line 1948, in __call__
    return self.func(*args)
           ^^^^^^^^^^^^^^^^
  File "C:\Users\wimjr\AppData\Local\Programs\Python\Python311\Lib\site-packages\customtkinter\windows\widgets\ctk_button.py", line 554, in _clicked
    self._command()
TypeError: LoginAndUserScreen.confirm_delete_user() missing 3 required positional arguments: 'username', 'password', and 'users'
[2024-07-21 14:45:48] No errors occurred
[2024-07-21 14:45:48] Closed the Error Log File




[2024-07-21 14:45:51] 


[2024-07-21 14:45:51] Started the Error Log File
Exception in Tkinter callback
Traceback (most recent call last):
  File "C:\Users\wimjr\AppData\Local\Programs\Python\Python311\Lib\tkinter\__init__.py", line 1948, in __call__
    return self.func(*args)
           ^^^^^^^^^^^^^^^^
  File "C:\Users\wimjr\AppData\Local\Programs\Python\Python311\Lib\site-packages\customtkinter\windows\widgets\ctk_button.py", line 554, in _clicked
    self._command()
  File "e:\Snake_game_V3\Snake_Game_V3\Login\login_snake_game.py", line 399, in delete_user_callback
    self.yes_button = ctk.CTkButton(self.user_frame, text="Yes", command=self.confirm_delete_user(), fg_color="grey90", text_color="blue", hover_color="#E6E6FA")
                                                                         ^^^^^^^^^^^^^^^^^^^^^^^^^^
  File "e:\Snake_game_V3\Snake_Game_V3\Login\login_snake_game.py", line 416, in confirm_delete_user
    self.delete_are_you_sure_widgets()
  File "e:\Snake_game_V3\Snake_Game_V3\Login\login_snake_game.py", line 423, in delete_are_you_sure_widgets
    self.yes_button.destroy()
    ^^^^^^^^^^^^^^^
AttributeError: 'LoginAndUserScreen' object has no attribute 'yes_button'
[2024-07-21 14:46:13] No errors occurred
[2024-07-21 14:46:13] Closed the Error Log File




[2024-07-21 16:51:45] 


[2024-07-21 16:51:45] Started the Error Log File
[2024-07-21 16:55:24] No errors occurred
[2024-07-21 16:55:24] Closed the Error Log File




[2024-07-21 16:55:26] 


[2024-07-21 16:55:26] Started the Error Log File
Exception in Tkinter callback
Traceback (most recent call last):
  File "C:\Users\wimjr\AppData\Local\Programs\Python\Python311\Lib\tkinter\__init__.py", line 1948, in __call__
    return self.func(*args)
           ^^^^^^^^^^^^^^^^
  File "C:\Users\wimjr\AppData\Local\Programs\Python\Python311\Lib\site-packages\customtkinter\windows\widgets\ctk_button.py", line 554, in _clicked
    self._command()
  File "e:\Snake_game_V3\Snake_Game_V3\Login\login_snake_game.py", line 412, in confirm_delete_user
    self.write_user_data(users)  # Assuming this method now accepts the entire users dict for updating
    ^^^^^^^^^^^^^^^^^^^^^^^^^^^
TypeError: LoginAndUserScreen.write_user_data() missing 1 required positional argument: 'password'
Exception in Tkinter callback
Traceback (most recent call last):
  File "C:\Users\wimjr\AppData\Local\Programs\Python\Python311\Lib\tkinter\__init__.py", line 1948, in __call__
    return self.func(*args)
           ^^^^^^^^^^^^^^^^
  File "C:\Users\wimjr\AppData\Local\Programs\Python\Python311\Lib\site-packages\customtkinter\windows\widgets\ctk_button.py", line 554, in _clicked
    self._command()
  File "e:\Snake_game_V3\Snake_Game_V3\Login\login_snake_game.py", line 412, in confirm_delete_user
    self.write_user_data(users)  # Assuming this method now accepts the entire users dict for updating
    ^^^^^^^^^^^^^^^^^^^^^^^^^^^
TypeError: LoginAndUserScreen.write_user_data() missing 1 required positional argument: 'password'
[2024-07-21 16:56:07] No errors occurred
[2024-07-21 16:56:07] Closed the Error Log File




[2024-07-21 16:56:57] 


[2024-07-21 16:56:57] Started the Error Log File
[2024-07-21 16:59:00] No errors occurred
[2024-07-21 16:59:00] Closed the Error Log File




[2024-07-21 16:59:03] 


[2024-07-21 16:59:03] Started the Error Log File
[2024-07-21 16:59:29] No errors occurred
[2024-07-21 16:59:29] Closed the Error Log File




[2024-07-21 16:59:32] 


[2024-07-21 16:59:32] Started the Error Log File
[2024-07-21 17:00:02] No errors occurred
[2024-07-21 17:00:02] Closed the Error Log File




[2024-07-21 17:05:56] 


[2024-07-21 17:05:56] Started the Error Log File
[2024-07-21 17:06:14] No errors occurred
[2024-07-21 17:06:14] Closed the Error Log File




[2024-07-21 17:08:09] 


[2024-07-21 17:08:09] Started the Error Log File
[2024-07-21 17:08:47] No errors occurred
[2024-07-21 17:08:47] Closed the Error Log File




[2024-07-21 17:08:48] 


[2024-07-21 17:08:48] Started the Error Log File
[2024-07-21 17:09:29] No errors occurred
[2024-07-21 17:09:29] Closed the Error Log File




[2024-07-21 17:09:31] 


[2024-07-21 17:09:31] Started the Error Log File
[2024-07-21 17:10:52] No errors occurred
[2024-07-21 17:10:52] Closed the Error Log File




[2024-07-21 17:12:43] 


[2024-07-21 17:12:43] Started the Error Log File
[2024-07-21 17:12:50] No errors occurred
[2024-07-21 17:12:50] Closed the Error Log File




[2024-07-21 17:13:42] 


[2024-07-21 17:13:42] Started the Error Log File
[2024-07-21 17:14:13] No errors occurred
[2024-07-21 17:14:13] Closed the Error Log File




[2024-07-21 20:52:02] 


[2024-07-21 20:52:02] Started the Error Log File
Exception in Tkinter callback
Traceback (most recent call last):
  File "C:\Users\wimjr\AppData\Local\Programs\Python\Python311\Lib\tkinter\__init__.py", line 1948, in __call__
    return self.func(*args)
           ^^^^^^^^^^^^^^^^
  File "e:\Snake_game_V3\Snake_Game_V3\Games\snake_endless_game.py", line 342, in start_game
    self.create_button_panel.update_button_state()
  File "e:\Snake_game_V3\Snake_Game_V3\Logic\buttonpanel_snake_game.py", line 222, in update_button_state
    self.classic_reset_high_score_button.configure(state=self.classic_reset_high_score_button_state) # pylint: disable=line-too-long
    ^^^^^^^^^^^^^^^^^^^^^^^^^^^^^^^^^^^^^^^^^^^^^^
AttributeError: 'NoneType' object has no attribute 'configure'
[2024-07-21 20:52:31] No errors occurred
[2024-07-21 20:52:31] Closed the Error Log File




[2024-07-21 21:02:19] 


[2024-07-21 21:02:19] Started the Error Log File
[2024-07-21 21:03:05] No errors occurred
[2024-07-21 21:03:05] Closed the Error Log File




[2024-07-21 21:04:21] 


[2024-07-21 21:04:21] Started the Error Log File
Exception in Tkinter callback
Traceback (most recent call last):
  File "C:\Users\wimjr\AppData\Local\Programs\Python\Python311\Lib\tkinter\__init__.py", line 1948, in __call__
    return self.func(*args)
           ^^^^^^^^^^^^^^^^
  File "e:\Snake_game_V3\Snake_Game_V3\Games\snake_endless_game.py", line 342, in start_game
    self.create_button_panel.update_button_state()
  File "e:\Snake_game_V3\Snake_Game_V3\Logic\buttonpanel_snake_game.py", line 225, in update_button_state
    self.classic_reset_high_score_button.configure(state=self.classic_reset_high_score_button_state) # pylint: disable=line-too-long
    ^^^^^^^^^^^^^^^^^^^^^^^^^^^^^^^^^^^^^^^^^^^^^^
AttributeError: 'NoneType' object has no attribute 'configure'
Exception in Tkinter callback
Traceback (most recent call last):
  File "C:\Users\wimjr\AppData\Local\Programs\Python\Python311\Lib\tkinter\__init__.py", line 1948, in __call__
    return self.func(*args)
           ^^^^^^^^^^^^^^^^
  File "e:\Snake_game_V3\Snake_Game_V3\Games\snake_endless_game.py", line 342, in start_game
    self.create_button_panel.update_button_state()
  File "e:\Snake_game_V3\Snake_Game_V3\Logic\buttonpanel_snake_game.py", line 225, in update_button_state
    self.classic_reset_high_score_button.configure(state=self.classic_reset_high_score_button_state) # pylint: disable=line-too-long
    ^^^^^^^^^^^^^^^^^^^^^^^^^^^^^^^^^^^^^^^^^^^^^^
AttributeError: 'NoneType' object has no attribute 'configure'
Exception in Tkinter callback
Traceback (most recent call last):
  File "C:\Users\wimjr\AppData\Local\Programs\Python\Python311\Lib\tkinter\__init__.py", line 1948, in __call__
    return self.func(*args)
           ^^^^^^^^^^^^^^^^
  File "e:\Snake_game_V3\Snake_Game_V3\Games\snake_leveling_game.py", line 257, in start_game
    self.create_button_panel.update_button_state()
  File "e:\Snake_game_V3\Snake_Game_V3\Logic\buttonpanel_snake_game.py", line 225, in update_button_state
    self.classic_reset_high_score_button.configure(state=self.classic_reset_high_score_button_state) # pylint: disable=line-too-long
    ^^^^^^^^^^^^^^^^^^^^^^^^^^^^^^^^^^^^^^^^^^^^^^
AttributeError: 'NoneType' object has no attribute 'configure'
[2024-07-21 21:05:01] No errors occurred
[2024-07-21 21:05:01] Closed the Error Log File




[2024-07-22 16:34:41] 


[2024-07-22 16:34:41] Started the Error Log File
[2024-07-22 16:35:17] No errors occurred
[2024-07-22 16:35:17] Closed the Error Log File




